<?xml version="1.0" ?>
<!-- =================================================================================== -->
<!-- |    This document was autogenerated by xacro from five_link_walker.xacro         | -->
<!-- |    EDITING THIS FILE BY HAND IS NOT RECOMMENDED                                 | -->
<!-- =================================================================================== -->
<robot name="five_link_walker" xmlns:xacro="http://ros.org/wiki/xacro">


	<link name="world">
	<inertial>
      <mass value="0"/>
      <inertia ixx="0.2125" ixy="-0.005" ixz="0.0225" iyy="0.205" iyz="0.045" izz="0.0125"/>
      <origin rpy="0 0 0" xyz="0 0 0"/>
    </inertial>
	</link>

	<link name="y_prismatic">
	 <inertial>
      <mass value="0.01"/>
      <inertia ixx="0.2125" ixy="-0.005" ixz="0.0225" iyy="0.205" iyz="0.045" izz="0.0125"/>
      <origin rpy="0 0 0" xyz="0 0 0"/>
    </inertial>
	</link>
	
	<joint name="y_to_world" type="prismatic">
    <parent link="world"/>
    <child link="y_prismatic"/>
    <axis xyz="0 1 0"/>
    <limit effort="0.0" lower="-10" upper="10" velocity="1000.0"/>
    <origin rpy="0 0 0" xyz="0 0 0"/>
  </joint>
		
	<link name="z_prismatic">
	 <inertial>
      <mass value="0.01"/>
      <inertia ixx="0.2125" ixy="-0.005" ixz="0.0225" iyy="0.205" iyz="0.045" izz="0.0125"/>
      <origin rpy="0 0 0" xyz="0 0 0"/>
    </inertial>
	</link>
	
	<joint name="z_to_y" type="prismatic">
    <parent link="y_prismatic"/>
    <child link="z_prismatic"/>
    <axis xyz="0 0 1"/>
    <limit effort="0.0" lower="-10" upper="10" velocity="1000.0"/>
    <origin rpy="0 0 0" xyz="0 0 0"/>
  </joint>
	
	<joint name="torso_to_z" type="continuous">
    <parent link="z_prismatic"/>
    <child link="torso"/>
    <axis xyz="1 0 0"/>
    <origin rpy="0 0 0" xyz="0 0 0"/>
  </joint>


  <link name="torso">
    <inertial>
      <origin xyz="0 0 0.24" rpy="0 0 0"/>
      <mass value="12"/>
      <inertia ixx="0" ixy="0" ixz="0" iyy="1.33" iyz="0" izz="0"/>
    </inertial>
    <visual>
      <origin xyz="0 0 0.315"/>
      <geometry>
        <cylinder length="0.63" radius="0.025"/>
      </geometry>
      <material name="black">
        <color rgba="0 0 0 1"/>
      </material>
    </visual>
    <collision>
      <origin xyz="0 0 0.315"/>
      <geometry>
        <cylinder length="0.63" radius="0.025"/>
      </geometry>
      <contact_coefficients mu="0.6" />
    </collision>
  </link>
  <link name="right_thigh">
    <inertial>
      <origin xyz="0 0 0.11" rpy="0 0 0"/>
      <mass value="6.8"/>
      <inertia ixx="0" ixy="0" ixz="0" iyy="0.47" iyz="0" izz="0"/>
    </inertial>
    <visual>
      <origin xyz="0 0 0.2"/>
      <geometry>
        <cylinder length="0.4" radius="0.025"/>
      </geometry>
      <material name="blue">
        <color rgba="0 0 1 1"/>
      </material>
    </visual>
    <collision>
      <origin xyz="0 0 0.2"/>
      <geometry>
        <cylinder length="0.4" radius="0.025"/>
      </geometry>
      <contact_coefficients mu="0.6" />
    </collision>
  </link>
  <link name="left_thigh">
    <inertial>
      <origin xyz="0 0 0.11" rpy="0 0 0"/>
      <mass value="6.8"/>
      <inertia ixx="0" ixy="0" ixz="0" iyy="0.47" iyz="0" izz="0"/>
    </inertial>
    <visual>
      <origin xyz="0 0 0.2"/>
      <geometry>
        <cylinder length="0.4" radius="0.025"/>
      </geometry>
      <material name="red">
        <color rgba="1 0 0 1"/>
      </material>
    </visual>
    <collision>
      <origin xyz="0 0 0.2"/>
      <geometry>
        <cylinder length="0.4" radius="0.025"/>
      </geometry>
      <contact_coefficients mu="0.6" />
    </collision>
  </link>
  <link name="right_shin">
    <inertial>
      <origin xyz="0 0 0.24" rpy="0 0 0"/>
      <mass value="3.2"/>
      <inertia ixx="0" ixy="0" ixz="0" iyy="0.2" iyz="0" izz="0"/>
    </inertial>
    <visual>
      <origin xyz="0 0 0.185"/>
      <geometry>
        <cylinder length="0.37" radius="0.025"/>
      </geometry>
      <material name="blue">
        <color rgba="1 0 0 1"/>
      </material>
    </visual>
    <collision>
      <origin xyz="0 0 0.185"/>
      <geometry>
        <cylinder length="0.37" radius="0.025"/>
      </geometry>
      <contact_coefficients mu="0.6" />
    </collision>
  </link>
  <link name="left_shin">
    <inertial>
      <origin xyz="0 0 0.24" rpy="0 0 0"/>
      <mass value="3.2"/>
      <inertia ixx="0" ixy="0" ixz="0" iyy="0.2" iyz="0" izz="0"/>
    </inertial>
    <visual>
      <origin xyz="0 0 0.185"/>
      <geometry>
        <cylinder length="0.37" radius="0.025"/>
      </geometry>
      <material name="red">
        <color rgba="0 0 1 1"/>
      </material>
    </visual>
    <collision>
      <origin xyz="0 0 0.185"/>
      <geometry>
        <cylinder length="0.37" radius="0.025"/>
      </geometry>
      <contact_coefficients mu="0.6" />
    </collision>
  </link>

  <joint name="q1_right" type="continuous">
    <origin xyz="0 0 0" rpy="0 0 0"/>
    <!-- <axis xyz="0 1 0"/> -->
    <axis xyz="1 0 0"/>
    <parent link="torso"/>
    <child link="right_thigh"/>
  </joint>
   <joint name="q2_right" type="continuous">
    <origin xyz="0 0 0.4" rpy="0 0 0"/>
    <!-- <axis xyz="0 1 0"/> -->
    <axis xyz="1 0 0"/>
    <parent link="right_thigh"/>
    <child link="right_shin"/>
  </joint>
    <joint name="q1_left" type="continuous">
    <origin xyz="0 0 0" rpy="0 0 0"/>
    <!-- <axis xyz="0 1 0"/> -->
    <axis xyz="1 0 0"/>
    <parent link="torso"/>
    <child link="left_thigh"/>
  </joint>
  <joint name="q2_left" type="continuous">
    <origin xyz="0 0 0.4" rpy="0 0 0"/>
    <!-- <axis xyz="0 1 0"/> -->
    <axis xyz="1 0 0"/>
    <parent link="left_thigh"/>
    <child link="left_shin"/>
  </joint>
  
  

  <link name="toe_left">
    <!-- Same toe contact information from minicheetah -->
      <contact>
      <friction_anchor/>
      <stiffness value="30000.0"/>
      <damping value="1000.0"/>
      <spinning_friction value="0.3"/>
      <lateral_friction value="3.0"/>
    </contact>
    <visual>
      <origin rpy="0 0 0" xyz="0 0 0"/>
      <geometry>
        <sphere radius="0.03"/>
      </geometry>
      <material name="darkgray"/>
    </visual>
    <collision>
      <origin rpy="0 0 0" xyz="0 0 0"/>
      <geometry>
        <sphere radius="0.03"/>
      </geometry>
    </collision>
    <inertial>
      <mass value="0.01"/>
      <inertia ixx="0.000025" ixy="0" ixz="0" iyy="0.000025" iyz="0" izz="0.000025"/>
    </inertial>
  </link>

  <link name="toe_right">
    <!-- Same toe contact information from minicheetah -->
      <contact>
      <friction_anchor/>
      <stiffness value="30000.0"/>
      <damping value="1000.0"/>
      <spinning_friction value="0.3"/>
      <lateral_friction value="3.0"/>
    </contact>
    <visual>
      <origin rpy="0 0 0" xyz="0 0 0"/>
      <geometry>
        <sphere radius="0.03"/>
      </geometry>
      <material name="darkgray"/>
    </visual>
    <collision>
      <origin rpy="0 0 0" xyz="0 0 0"/>
      <geometry>
        <sphere radius="0.03"/>
      </geometry>
    </collision>
    <inertial>
      <mass value="0.015"/>
      <inertia ixx="0.000025" ixy="0" ixz="0" iyy="0.000025" iyz="0" izz="0.000025"/>
    </inertial>
  </link>

  <joint name="shin_toe_left" type="fixed">
    <parent link="left_shin"/>
    <child link="toe_left"/>
    <origin xyz="0 0 0.37"/>
    <dynamics damping="0.0" friction="0.0"/>
  </joint>

  <joint name="shin_toe_right" type="fixed">
    <parent link="right_shin"/>
    <child link="toe_right"/>
    <origin xyz="0 0 0.37"/>
    <dynamics damping="0.0" friction="0.0"/>
  </joint>
  

<transmission name="q1_right_trans" type="pr2_mechanism_model/SimpleTransmission">
	<joint name="q1_right"/>
	<actuator name="q1_right_motor"/>
	<mechanicalReduction>50</mechanicalReduction>
    <motorInertia>0.000332</motorInertia>
</transmission>

<transmission name="q2_right_trans" type="pr2_mechanism_model/SimpleTransmission">
	<joint name="q2_right"/>
	<actuator name="q2_right_motor"/>
	<mechanicalReduction>50</mechanicalReduction>
    <motorInertia>0.000332</motorInertia>
</transmission>

<transmission name="q1_left_trans" type="pr2_mechanism_model/SimpleTransmission">
	<joint name="q1_left"/>
	<actuator name="q1_left_motor"/>
	<mechanicalReduction>50</mechanicalReduction>
    <motorInertia>0.000332</motorInertia>
</transmission>

<transmission name="q2_left_trans" type="pr2_mechanism_model/SimpleTransmission">
	<joint name="q2_left"/>
	<actuator name="q2_left_motor"/>
	<mechanicalReduction>50</mechanicalReduction>
    <motorInertia>0.000332</motorInertia>
</transmission>

</robot>
